Workbook
Name ApparentRecipeLevel: NotesCalculator!$C$98
Name this.ExpBonus: NotesCalculator!$F$111
Name ExpBuffs: NotesCalculator!$C$101
Name this.LevelDifference: NotesCalculator!$D$103
Name RecipeExpModTable: RecipeExpModTable!$A$2:$B$23
Name QualityGain: NotesCalculator!$C$99
Name ClassJobLevel: NotesCalculator!$C$97
Name TotalQuality: NotesCalculator!$C$100
Name this.ExpLevelMod: NotesCalculator!$F$105
Name this.ExpReward: NotesCalculator!$H$113
Name this.CraftExp: NotesCalculator!$H$107
Name RecipeBaseExpTable: RecipeBaseExpTable!$A$2:$B$101
Name RecipeBonusExpTable: RecipeBonusExpTable!$A$2:$B$102
Name SEQUENCE: RecipeBonusExpTable!$A$2:$A$102
Name this.QualityFactor: NotesCalculator!$D$109
Name QUALITYFACTOR: LAMBDA(FLOOR(QualityGain / TotalQuality * 100))
Name EXPREWARD: LAMBDA(FLOOR((this.CraftExp * (1 + this.ExpBonus)) + FLOOR(this.CraftExp * ExpBuffs)))
Name LEVELDIFFERENCE: LAMBDA(MIN(21,MAX(0,ClassJobLevel - ApparentRecipeLevel)))
Name EXPBONUS: LAMBDA(VLOOKUP(this.QualityFactor,RecipeBonusExpTable,2,0) / 100)
Name EXPLEVELMOD: LAMBDA(VLOOKUP(this.LevelDifference,RecipeExpModTable,2,0))
Name CRAFTEXP: LAMBDA(FLOOR(VLOOKUP(ApparentRecipeLevel,RecipeBaseExpTable,2,0) / 3 * this.ExpLevelMod / 100))

Sheet RecipeMappedExp.csv
A1: key | B1: 0 | C1: 1 | D1: 2 | E1: 3 | F1: 4 | G1: 5 | H1: 6 | I1: 7 | J1: 8 | K1: 9 | L1: 10 | M1: 11 | N1: 12 | O1: 13 | P1: 14 | Q1: 15 | R1: 16 | S1: 17 | T1: 18 | U1: 19 | V1: 20 | W1: 21 | X1: 22
A2: # | B2: Exp{Base} | C2: Exp[0] | D2: Exp[1] | E2: Exp[2] | F2: Exp[3] | G2: Exp[4] | H2: Exp[5] | I2: Exp[6] | J2: Exp[7] | K2: Exp[8] | L2: Exp[9] | M2: Exp[10] | N2: Exp[11] | O2: Exp[12] | P2: Exp[13] | Q2: Exp[14] | R2: Exp[15] | S2: Exp[16] | T2: Exp[17] | U2: Exp[18] | V2: Exp[19] | W2: Exp[20] | X2: Exp[21]
A3: int16 | B3: uint32 | C3: uint32 | D3: uint32 | E3: uint32 | F3: uint32 | G3: uint32 | H3: uint32 | I3: uint32 | J3: uint32 | K3: uint32 | L3: uint32 | M3: uint32 | N3: uint32 | O3: uint32 | P3: uint32 | Q3: uint32 | R3: uint32 | S3: uint32 | T3: uint32 | U3: uint32 | V3: uint32 | W3: uint32 | X3: uint32
A4: 1 | B4: 540 | C4: 180 | D4: 172 | E4: 165 | F4: 158 | G4: 151 | H4: 144 | I4: 135 | J4: 126 | K4: 117 | L4: 108 | M4: 99 | N4: 81 | O4: 63 | P4: 45 | Q4: 36 | R4: 32 | S4: 28 | T4: 27 | U4: 25 | V4: 23 | W4: 21 | X4: 18
A5: 2 | B5: 582 | C5: 194 | D5: 186 | E5: 178 | F5: 170 | G5: 162 | H5: 155 | I5: 145 | J5: 135 | K5: 126 | L5: 116 | M5: 106 | N5: 87 | O5: 67 | P5: 48 | Q5: 38 | R5: 34 | S5: 31 | T5: 29 | U5: 27 | V5: 25 | W5: 23 | X5: 19
A6: 3 | B6: 630 | C6: 210 | D6: 201 | E6: 193 | F6: 184 | G6: 176 | H6: 168 | I6: 157 | J6: 147 | K6: 136 | L6: 126 | M6: 115 | N6: 94 | O6: 73 | P6: 52 | Q6: 42 | R6: 37 | S6: 33 | T6: 31 | U6: 29 | V6: 27 | W6: 25 | X6: 21
A7: 4 | B7: 795 | C7: 265 | D7: 254 | E7: 243 | F7: 233 | G7: 222 | H7: 212 | I7: 198 | J7: 185 | K7: 172 | L7: 159 | M7: 145 | N7: 119 | O7: 92 | P7: 66 | Q7: 53 | R7: 47 | S7: 42 | T7: 39 | U7: 37 | V7: 34 | W7: 31 | X7: 26
A8: 5 | B8: 996 | C8: 332 | D8: 318 | E8: 305 | F8: 292 | G8: 278 | H8: 265 | I8: 249 | J8: 232 | K8: 215 | L8: 199 | M8: 182 | N8: 149 | O8: 116 | P8: 83 | Q8: 66 | R8: 59 | S8: 53 | T8: 49 | U8: 46 | V8: 43 | W8: 39 | X8: 33
A9: 6 | B9: 1050 | C9: 350 | D9: 336 | E9: 322 | F9: 308 | G9: 294 | H9: 280 | I9: 262 | J9: 245 | K9: 227 | L9: 210 | M9: 192 | N9: 157 | O9: 122 | P9: 87 | Q9: 70 | R9: 63 | S9: 56 | T9: 52 | U9: 49 | V9: 45 | W9: 42 | X9: 35
A10: 7 | B10: 1176 | C10: 392 | D10: 376 | E10: 360 | F10: 344 | G10: 329 | H10: 313 | I10: 294 | J10: 274 | K10: 254 | L10: 235 | M10: 215 | N10: 176 | O10: 137 | P10: 98 | Q10: 78 | R10: 70 | S10: 62 | T10: 58 | U10: 54 | V10: 50 | W10: 47 | X10: 39
A11: 8 | B11: 1263 | C11: 421 | D11: 404 | E11: 387 | F11: 370 | G11: 353 | H11: 336 | I11: 315 | J11: 294 | K11: 273 | L11: 252 | M11: 231 | N11: 189 | O11: 147 | P11: 105 | Q11: 84 | R11: 75 | S11: 67 | T11: 63 | U11: 58 | V11: 54 | W11: 50 | X11: 42
A12: 9 | B12: 1356 | C12: 452 | D12: 433 | E12: 415 | F12: 397 | G12: 379 | H12: 361 | I12: 339 | J12: 316 | K12: 293 | L12: 271 | M12: 248 | N12: 203 | O12: 158 | P12: 113 | Q12: 90 | R12: 81 | S12: 72 | T12: 67 | U12: 63 | V12: 58 | W12: 54 | X12: 45
A13: 10 | B13: 1437 | C13: 479 | D13: 459 | E13: 440 | F13: 421 | G13: 402 | H13: 383 | I13: 359 | J13: 335 | K13: 311 | L13: 287 | M13: 263 | N13: 215 | O13: 167 | P13: 119 | Q13: 95 | R13: 86 | S13: 76 | T13: 71 | U13: 67 | V13: 62 | W13: 57 | X13: 47
A14: 11 | B14: 1629 | C14: 543 | D14: 521 | E14: 499 | F14: 477 | G14: 456 | H14: 434 | I14: 407 | J14: 380 | K14: 352 | L14: 325 | M14: 298 | N14: 244 | O14: 190 | P14: 135 | Q14: 108 | R14: 97 | S14: 86 | T14: 81 | U14: 76 | V14: 70 | W14: 65 | X14: 54
A15: 12 | B15: 1725 | C15: 575 | D15: 552 | E15: 529 | F15: 506 | G15: 483 | H15: 460 | I15: 431 | J15: 402 | K15: 373 | L15: 345 | M15: 316 | N15: 258 | O15: 201 | P15: 143 | Q15: 115 | R15: 103 | S15: 92 | T15: 86 | U15: 80 | V15: 74 | W15: 69 | X15: 57
... A103: 100 | B103: 522414 | C103: 174138 | D103: 167172 | E103: 160206 | F103: 153241 | G103: 146275 | H103: 139310 | I103: 130603 | J103: 121896 | K103: 113189 | L103: 104482 | M103: 95775 | N103: 78362 | O103: 60948 | P103: 43534 | Q103: 34827 | R103: 31344 | S103: 27862 | T103: 26120 | U103: 24379 | V103: 22637 | W103: 20896 | X103: 17413

Sheet SanityCheck
A1: Lv.# | B1: Level Difference | E1: 0 | F1: 1 | G1: 2 | H1: 3 | I1: 4 | J1: 5 | K1: 6 | L1: 7 | M1: 8 | N1: 9 | O1: 10 | P1: 11 | Q1: 12 | R1: 13 | S1: 14 | T1: 15 | U1: 16 | V1: 17 | W1: 18 | X1: 19 | Y1: 20 | Z1: 21
B2: Lv. Diff MOD | D2: 300 | E2: 100 | F2: 96 | G2: 92 | H2: 88 | I2: 84 | J2: 80 | K2: 75 | L2: 70 | M2: 65 | N2: 60 | O2: 55 | P2: 45 | Q2: 35 | R2: 25 | S2: 20 | T2: 18 | U2: 16 | V2: 15 | W2: 14 | X2: 13 | Y2: 12 | Z2: 10
B3: Step | D3: 200 | E3: 0 | F3: 4 | G3: 4 | H3: 4 | I3: 4 | J3: 4 | K3: 5 | L3: 5 | M3: 5 | N3: 5 | O3: 5 | P3: 10 | Q3: 10 | R3: 10 | S3: 5 | T3: 2 | U3: 2 | V3: 1 | W3: 1 | X3: 1 | Y3: 1 | Z3: 2
A4: 1 | B4: Act. EXP | D4: {=INDEX(RecipeMappedExp.csv!$B$4:$B$103,$A4,1)} -> 540 | E4: {=IFERROR(INDEX(RecipeMappedExp.csv!$C$4:$X$103,$A4,1 + E$1),"")} -> 180 | F4: {=IFERROR(INDEX(RecipeMappedExp.csv!$C$4:$X$103,$A4,1 + F$1),"")} -> 172 | G4: {=IFERROR(INDEX(RecipeMappedExp.csv!$C$4:$X$103,$A4,1 + G$1),"")} -> 165 | H4: {=IFERROR(INDEX(RecipeMappedExp.csv!$C$4:$X$103,$A4,1 + H$1),"")} -> 158 | I4: {=IFERROR(INDEX(RecipeMappedExp.csv!$C$4:$X$103,$A4,1 + I$1),"")} -> 151 | J4: {=IFERROR(INDEX(RecipeMappedExp.csv!$C$4:$X$103,$A4,1 + J$1),"")} -> 144 | K4: {=IFERROR(INDEX(RecipeMappedExp.csv!$C$4:$X$103,$A4,1 + K$1),"")} -> 135 | L4: {=IFERROR(INDEX(RecipeMappedExp.csv!$C$4:$X$103,$A4,1 + L$1),"")} -> 126 | ... Z4: {=IFERROR(INDEX(RecipeMappedExp.csv!$C$4:$X$103,$A4,1 + Z$1),"")} -> 18
B5: Exp. EXP | D5: =D4 -> 540 | E5: {=FLOOR($D4 / 3 * $E$2:$Z$2 / 100,1)} -> 180 | F5: 172 | G5: 165 | H5: 158 | I5: 151 | J5: 144 | K5: 135 | L5: 126 | M5: 117 | N5: 108 | O5: 99 | P5: 81 | Q5: 63 | R5: 45 | S5: 36 | T5: 32 | U5: 28 | V5: 27 | W5: 25 | X5: 23 | Y5: 21 | Z5: 18 | AA5: {=IF($D5:$Z5 = $D4:$Z4,TRUE,FALSE)} -> TRUE | AB5: TRUE | AC5: TRUE | AD5: TRUE | AE5: TRUE | AF5: TRUE | AG5: TRUE | AH5: TRUE | AI5: TRUE | AJ5: TRUE | AK5: TRUE | AL5: TRUE | AM5: TRUE | AN5: TRUE | AO5: TRUE | AP5: TRUE | AQ5: TRUE | AR5: TRUE | AS5: TRUE | AT5: TRUE | AU5: TRUE | AV5: TRUE | AW5: TRUE
B6: Exp. MOD | D6: {=IFERROR(ROUND(D4:Z4 / $E4 * 100,0),"")} -> 300 | E6: 100 | F6: 96 | G6: 92 | H6: 88 | I6: 84 | J6: 80 | K6: 75 | L6: 70 | M6: 65 | N6: 60 | O6: 55 | P6: 45 | Q6: 35 | R6: 25 | S6: 20 | T6: 18 | U6: 16 | V6: 15 | W6: 14 | X6: 13 | Y6: 12 | Z6: 10
A7: 2 | B7: Act. EXP | D7: {=INDEX(RecipeMappedExp.csv!$B$4:$B$103,$A7,1)} -> 582 | E7: {=IFERROR(INDEX(RecipeMappedExp.csv!$C$4:$X$103,$A7,1 + E$1),"")} -> 194 | F7: {=IFERROR(INDEX(RecipeMappedExp.csv!$C$4:$X$103,$A7,1 + F$1),"")} -> 186 | G7: {=IFERROR(INDEX(RecipeMappedExp.csv!$C$4:$X$103,$A7,1 + G$1),"")} -> 178 | H7: {=IFERROR(INDEX(RecipeMappedExp.csv!$C$4:$X$103,$A7,1 + H$1),"")} -> 170 | I7: {=IFERROR(INDEX(RecipeMappedExp.csv!$C$4:$X$103,$A7,1 + I$1),"")} -> 162 | J7: {=IFERROR(INDEX(RecipeMappedExp.csv!$C$4:$X$103,$A7,1 + J$1),"")} -> 155 | K7: {=IFERROR(INDEX(RecipeMappedExp.csv!$C$4:$X$103,$A7,1 + K$1),"")} -> 145 | L7: {=IFERROR(INDEX(RecipeMappedExp.csv!$C$4:$X$103,$A7,1 + L$1),"")} -> 135 | ... Z7: {=IFERROR(INDEX(RecipeMappedExp.csv!$C$4:$X$103,$A7,1 + Z$1),"")} -> 19
B8: Exp. EXP | D8: =D7 -> 582 | E8: {=FLOOR($D7 / 3 * $E$2:$Z$2 / 100,1)} -> 194 | F8: 186 | G8: 178 | H8: 170 | I8: 162 | J8: 155 | K8: 145 | L8: 135 | M8: 126 | N8: 116 | O8: 106 | P8: 87 | Q8: 67 | R8: 48 | S8: 38 | T8: 34 | U8: 31 | V8: 29 | W8: 27 | X8: 25 | Y8: 23 | Z8: 19 | AA8: {=IF($D8:$Z8 = $D7:$Z7,TRUE,FALSE)} -> TRUE | AB8: TRUE | AC8: TRUE | AD8: TRUE | AE8: TRUE | AF8: TRUE | AG8: TRUE | AH8: TRUE | AI8: TRUE | AJ8: TRUE | AK8: TRUE | AL8: TRUE | AM8: TRUE | AN8: TRUE | AO8: TRUE | AP8: TRUE | AQ8: TRUE | AR8: TRUE | AS8: TRUE | AT8: TRUE | AU8: TRUE | AV8: TRUE | AW8: TRUE
B9: Exp. MOD | D9: {=IFERROR(ROUND(D7:Z7 / $E7 * 100,0),"")} -> 300 | E9: 100 | F9: 96 | G9: 92 | H9: 88 | I9: 84 | J9: 80 | K9: 75 | L9: 70 | M9: 65 | N9: 60 | O9: 55 | P9: 45 | Q9: 35 | R9: 25 | S9: 20 | T9: 18 | U9: 16 | V9: 15 | W9: 14 | X9: 13 | Y9: 12 | Z9: 10
A10: 3 | B10: Act. EXP | D10: {=INDEX(RecipeMappedExp.csv!$B$4:$B$103,$A10,1)} -> 630 | E10: {=IFERROR(INDEX(RecipeMappedExp.csv!$C$4:$X$103,$A10,1 + E$1),"")} -> 210 | F10: {=IFERROR(INDEX(RecipeMappedExp.csv!$C$4:$X$103,$A10,1 + F$1),"")} -> 201 | G10: {=IFERROR(INDEX(RecipeMappedExp.csv!$C$4:$X$103,$A10,1 + G$1),"")} -> 193 | H10: {=IFERROR(INDEX(RecipeMappedExp.csv!$C$4:$X$103,$A10,1 + H$1),"")} -> 184 | I10: {=IFERROR(INDEX(RecipeMappedExp.csv!$C$4:$X$103,$A10,1 + I$1),"")} -> 176 | J10: {=IFERROR(INDEX(RecipeMappedExp.csv!$C$4:$X$103,$A10,1 + J$1),"")} -> 168 | K10: {=IFERROR(INDEX(RecipeMappedExp.csv!$C$4:$X$103,$A10,1 + K$1),"")} -> 157 | L10: {=IFERROR(INDEX(RecipeMappedExp.csv!$C$4:$X$103,$A10,1 + L$1),"")} -> 147 | ... Z10: {=IFERROR(INDEX(RecipeMappedExp.csv!$C$4:$X$103,$A10,1 + Z$1),"")} -> 21
B11: Exp. EXP | D11: =D10 -> 630 | E11: {=FLOOR($D10 / 3 * $E$2:$Z$2 / 100,1)} -> 210 | F11: 201 | G11: 193 | H11: 184 | I11: 176 | J11: 168 | K11: 157 | L11: 147 | M11: 136 | N11: 126 | O11: 115 | P11: 94 | Q11: 73 | R11: 52 | S11: 42 | T11: 37 | U11: 33 | V11: 31 | W11: 29 | X11: 27 | Y11: 25 | Z11: 21 | AA11: {=IF($D11:$Z11 = $D10:$Z10,TRUE,FALSE)} -> TRUE | AB11: TRUE | AC11: TRUE | AD11: TRUE | AE11: TRUE | AF11: TRUE | AG11: TRUE | AH11: TRUE | AI11: TRUE | AJ11: TRUE | AK11: TRUE | AL11: TRUE | AM11: TRUE | AN11: TRUE | AO11: TRUE | AP11: TRUE | AQ11: TRUE | AR11: TRUE | AS11: TRUE | AT11: TRUE | AU11: TRUE | AV11: TRUE | AW11: TRUE
B12: Exp. MOD | D12: {=IFERROR(ROUND(D10:Z10 / $E10 * 100,0),"")} -> 300 | E12: 100 | F12: 96 | G12: 92 | H12: 88 | I12: 84 | J12: 80 | K12: 75 | L12: 70 | M12: 65 | N12: 60 | O12: 55 | P12: 45 | Q12: 35 | R12: 25 | S12: 20 | T12: 18 | U12: 16 | V12: 15 | W12: 14 | X12: 13 | Y12: 12 | Z12: 10
A13: 4 | B13: Act. EXP | D13: {=INDEX(RecipeMappedExp.csv!$B$4:$B$103,$A13,1)} -> 795 | E13: {=IFERROR(INDEX(RecipeMappedExp.csv!$C$4:$X$103,$A13,1 + E$1),"")} -> 265 | F13: {=IFERROR(INDEX(RecipeMappedExp.csv!$C$4:$X$103,$A13,1 + F$1),"")} -> 254 | G13: {=IFERROR(INDEX(RecipeMappedExp.csv!$C$4:$X$103,$A13,1 + G$1),"")} -> 243 | H13: {=IFERROR(INDEX(RecipeMappedExp.csv!$C$4:$X$103,$A13,1 + H$1),"")} -> 233 | I13: {=IFERROR(INDEX(RecipeMappedExp.csv!$C$4:$X$103,$A13,1 + I$1),"")} -> 222 | J13: {=IFERROR(INDEX(RecipeMappedExp.csv!$C$4:$X$103,$A13,1 + J$1),"")} -> 212 | K13: {=IFERROR(INDEX(RecipeMappedExp.csv!$C$4:$X$103,$A13,1 + K$1),"")} -> 198 | L13: {=IFERROR(INDEX(RecipeMappedExp.csv!$C$4:$X$103,$A13,1 + L$1),"")} -> 185 | ... Z13: {=IFERROR(INDEX(RecipeMappedExp.csv!$C$4:$X$103,$A13,1 + Z$1),"")} -> 26
B14: Exp. EXP | D14: =D13 -> 795 | E14: {=FLOOR($D13 / 3 * $E$2:$Z$2 / 100,1)} -> 265 | F14: 254 | G14: 243 | H14: 233 | I14: 222 | J14: 212 | K14: 198 | L14: 185 | M14: 172 | N14: 159 | O14: 145 | P14: 119 | Q14: 92 | R14: 66 | S14: 53 | T14: 47 | U14: 42 | V14: 39 | W14: 37 | X14: 34 | Y14: 31 | Z14: 26 | AA14: {=IF($D14:$Z14 = $D13:$Z13,TRUE,FALSE)} -> TRUE | AB14: TRUE | AC14: TRUE | AD14: TRUE | AE14: TRUE | AF14: TRUE | AG14: TRUE | AH14: TRUE | AI14: TRUE | AJ14: TRUE | AK14: TRUE | AL14: TRUE | AM14: TRUE | AN14: TRUE | AO14: TRUE | AP14: TRUE | AQ14: TRUE | AR14: TRUE | AS14: TRUE | AT14: TRUE | AU14: TRUE | AV14: TRUE | AW14: TRUE
B15: Exp. MOD | D15: {=IFERROR(ROUND(D13:Z13 / $E13 * 100,0),"")} -> 300 | E15: 100 | F15: 96 | G15: 92 | H15: 88 | I15: 84 | J15: 80 | K15: 75 | L15: 70 | M15: 65 | N15: 60 | O15: 55 | P15: 45 | Q15: 35 | R15: 25 | S15: 20 | T15: 18 | U15: 16 | V15: 15 | W15: 14 | X15: 13 | Y15: 12 | Z15: 10
A16: 5 | B16: Act. EXP | D16: {=INDEX(RecipeMappedExp.csv!$B$4:$B$103,$A16,1)} -> 996 | E16: {=IFERROR(INDEX(RecipeMappedExp.csv!$C$4:$X$103,$A16,1 + E$1),"")} -> 332 | F16: {=IFERROR(INDEX(RecipeMappedExp.csv!$C$4:$X$103,$A16,1 + F$1),"")} -> 318 | G16: {=IFERROR(INDEX(RecipeMappedExp.csv!$C$4:$X$103,$A16,1 + G$1),"")} -> 305 | H16: {=IFERROR(INDEX(RecipeMappedExp.csv!$C$4:$X$103,$A16,1 + H$1),"")} -> 292 | I16: {=IFERROR(INDEX(RecipeMappedExp.csv!$C$4:$X$103,$A16,1 + I$1),"")} -> 278 | J16: {=IFERROR(INDEX(RecipeMappedExp.csv!$C$4:$X$103,$A16,1 + J$1),"")} -> 265 | K16: {=IFERROR(INDEX(RecipeMappedExp.csv!$C$4:$X$103,$A16,1 + K$1),"")} -> 249 | L16: {=IFERROR(INDEX(RecipeMappedExp.csv!$C$4:$X$103,$A16,1 + L$1),"")} -> 232 | ... Z16: {=IFERROR(INDEX(RecipeMappedExp.csv!$C$4:$X$103,$A16,1 + Z$1),"")} -> 33
B17: Exp. EXP | D17: =D16 -> 996 | E17: {=FLOOR($D16 / 3 * $E$2:$Z$2 / 100,1)} -> 332 | F17: 318 | G17: 305 | H17: 292 | I17: 278 | J17: 265 | K17: 249 | L17: 232 | M17: 215 | N17: 199 | O17: 182 | P17: 149 | Q17: 116 | R17: 83 | S17: 66 | T17: 59 | U17: 53 | V17: 49 | W17: 46 | X17: 43 | Y17: 39 | Z17: 33 | AA17: {=IF($D17:$Z17 = $D16:$Z16,TRUE,FALSE)} -> TRUE | AB17: TRUE | AC17: TRUE | AD17: TRUE | AE17: TRUE | AF17: TRUE | AG17: TRUE | AH17: TRUE | AI17: TRUE | AJ17: TRUE | AK17: TRUE | AL17: TRUE | AM17: TRUE | AN17: TRUE | AO17: TRUE | AP17: TRUE | AQ17: TRUE | AR17: TRUE | AS17: TRUE | AT17: TRUE | AU17: TRUE | AV17: TRUE | AW17: TRUE
B18: Exp. MOD | D18: {=IFERROR(ROUND(D16:Z16 / $E16 * 100,0),"")} -> 300 | E18: 100 | F18: 96 | G18: 92 | H18: 88 | I18: 84 | J18: 80 | K18: 75 | L18: 70 | M18: 65 | N18: 60 | O18: 55 | P18: 45 | Q18: 35 | R18: 25 | S18: 20 | T18: 18 | U18: 16 | V18: 15 | W18: 14 | X18: 13 | Y18: 12 | Z18: 10
A19: 6 | B19: Act. EXP | D19: {=INDEX(RecipeMappedExp.csv!$B$4:$B$103,$A19,1)} -> 1050 | E19: {=IFERROR(INDEX(RecipeMappedExp.csv!$C$4:$X$103,$A19,1 + E$1),"")} -> 350 | F19: {=IFERROR(INDEX(RecipeMappedExp.csv!$C$4:$X$103,$A19,1 + F$1),"")} -> 336 | G19: {=IFERROR(INDEX(RecipeMappedExp.csv!$C$4:$X$103,$A19,1 + G$1),"")} -> 322 | H19: {=IFERROR(INDEX(RecipeMappedExp.csv!$C$4:$X$103,$A19,1 + H$1),"")} -> 308 | I19: {=IFERROR(INDEX(RecipeMappedExp.csv!$C$4:$X$103,$A19,1 + I$1),"")} -> 294 | J19: {=IFERROR(INDEX(RecipeMappedExp.csv!$C$4:$X$103,$A19,1 + J$1),"")} -> 280 | K19: {=IFERROR(INDEX(RecipeMappedExp.csv!$C$4:$X$103,$A19,1 + K$1),"")} -> 262 | L19: {=IFERROR(INDEX(RecipeMappedExp.csv!$C$4:$X$103,$A19,1 + L$1),"")} -> 245 | ... Z19: {=IFERROR(INDEX(RecipeMappedExp.csv!$C$4:$X$103,$A19,1 + Z$1),"")} -> 35
B20: Exp. EXP | D20: =D19 -> 1050 | E20: {=FLOOR($D19 / 3 * $E$2:$Z$2 / 100,1)} -> 350 | F20: 336 | G20: 322 | H20: 308 | I20: 294 | J20: 280 | K20: 262 | L20: 245 | M20: 227 | N20: 210 | O20: 192 | P20: 157 | Q20: 122 | R20: 87 | S20: 70 | T20: 63 | U20: 56 | V20: 52 | W20: 49 | X20: 45 | Y20: 42 | Z20: 35 | AA20: {=IF($D20:$Z20 = $D19:$Z19,TRUE,FALSE)} -> TRUE | AB20: TRUE | AC20: TRUE | AD20: TRUE | AE20: TRUE | AF20: TRUE | AG20: TRUE | AH20: TRUE | AI20: TRUE | AJ20: TRUE | AK20: TRUE | AL20: TRUE | AM20: TRUE | AN20: TRUE | AO20: TRUE | AP20: TRUE | AQ20: TRUE | AR20: TRUE | AS20: TRUE | AT20: TRUE | AU20: TRUE | AV20: TRUE | AW20: TRUE
B21: Exp. MOD | D21: {=IFERROR(ROUND(D19:Z19 / $E19 * 100,0),"")} -> 300 | E21: 100 | F21: 96 | G21: 92 | H21: 88 | I21: 84 | J21: 80 | K21: 75 | L21: 70 | M21: 65 | N21: 60 | O21: 55 | P21: 45 | Q21: 35 | R21: 25 | S21: 20 | T21: 18 | U21: 16 | V21: 15 | W21: 14 | X21: 13 | Y21: 12 | Z21: 10
A22: 7 | B22: Act. EXP | D22: {=INDEX(RecipeMappedExp.csv!$B$4:$B$103,$A22,1)} -> 1176 | E22: {=IFERROR(INDEX(RecipeMappedExp.csv!$C$4:$X$103,$A22,1 + E$1),"")} -> 392 | F22: {=IFERROR(INDEX(RecipeMappedExp.csv!$C$4:$X$103,$A22,1 + F$1),"")} -> 376 | G22: {=IFERROR(INDEX(RecipeMappedExp.csv!$C$4:$X$103,$A22,1 + G$1),"")} -> 360 | H22: {=IFERROR(INDEX(RecipeMappedExp.csv!$C$4:$X$103,$A22,1 + H$1),"")} -> 344 | I22: {=IFERROR(INDEX(RecipeMappedExp.csv!$C$4:$X$103,$A22,1 + I$1),"")} -> 329 | J22: {=IFERROR(INDEX(RecipeMappedExp.csv!$C$4:$X$103,$A22,1 + J$1),"")} -> 313 | K22: {=IFERROR(INDEX(RecipeMappedExp.csv!$C$4:$X$103,$A22,1 + K$1),"")} -> 294 | L22: {=IFERROR(INDEX(RecipeMappedExp.csv!$C$4:$X$103,$A22,1 + L$1),"")} -> 274 | ... Z22: {=IFERROR(INDEX(RecipeMappedExp.csv!$C$4:$X$103,$A22,1 + Z$1),"")} -> 39
B23: Exp. EXP | D23: =D22 -> 1176 | E23: {=FLOOR($D22 / 3 * $E$2:$Z$2 / 100,1)} -> 392 | F23: 376 | G23: 360 | H23: 344 | I23: 329 | J23: 313 | K23: 294 | L23: 274 | M23: 254 | N23: 235 | O23: 215 | P23: 176 | Q23: 137 | R23: 98 | S23: 78 | T23: 70 | U23: 62 | V23: 58 | W23: 54 | X23: 50 | Y23: 47 | Z23: 39 | AA23: {=IF($D23:$Z23 = $D22:$Z22,TRUE,FALSE)} -> TRUE | AB23: TRUE | AC23: TRUE | AD23: TRUE | AE23: TRUE | AF23: TRUE | AG23: TRUE | AH23: TRUE | AI23: TRUE | AJ23: TRUE | AK23: TRUE | AL23: TRUE | AM23: TRUE | AN23: TRUE | AO23: TRUE | AP23: TRUE | AQ23: TRUE | AR23: TRUE | AS23: TRUE | AT23: TRUE | AU23: TRUE | AV23: TRUE | AW23: TRUE
B24: Exp. MOD | D24: {=IFERROR(ROUND(D22:Z22 / $E22 * 100,0),"")} -> 300 | E24: 100 | F24: 96 | G24: 92 | H24: 88 | I24: 84 | J24: 80 | K24: 75 | L24: 70 | M24: 65 | N24: 60 | O24: 55 | P24: 45 | Q24: 35 | R24: 25 | S24: 20 | T24: 18 | U24: 16 | V24: 15 | W24: 14 | X24: 13 | Y24: 12 | Z24: 10
A25: 8 | B25: Act. EXP | D25: {=INDEX(RecipeMappedExp.csv!$B$4:$B$103,$A25,1)} -> 1263 | E25: {=IFERROR(INDEX(RecipeMappedExp.csv!$C$4:$X$103,$A25,1 + E$1),"")} -> 421 | F25: {=IFERROR(INDEX(RecipeMappedExp.csv!$C$4:$X$103,$A25,1 + F$1),"")} -> 404 | G25: {=IFERROR(INDEX(RecipeMappedExp.csv!$C$4:$X$103,$A25,1 + G$1),"")} -> 387 | H25: {=IFERROR(INDEX(RecipeMappedExp.csv!$C$4:$X$103,$A25,1 + H$1),"")} -> 370 | I25: {=IFERROR(INDEX(RecipeMappedExp.csv!$C$4:$X$103,$A25,1 + I$1),"")} -> 353 | J25: {=IFERROR(INDEX(RecipeMappedExp.csv!$C$4:$X$103,$A25,1 + J$1),"")} -> 336 | K25: {=IFERROR(INDEX(RecipeMappedExp.csv!$C$4:$X$103,$A25,1 + K$1),"")} -> 315 | L25: {=IFERROR(INDEX(RecipeMappedExp.csv!$C$4:$X$103,$A25,1 + L$1),"")} -> 294 | ... Z25: {=IFERROR(INDEX(RecipeMappedExp.csv!$C$4:$X$103,$A25,1 + Z$1),"")} -> 42
B26: Exp. EXP | D26: =D25 -> 1263 | E26: {=FLOOR($D25 / 3 * $E$2:$Z$2 / 100,1)} -> 421 | F26: 404 | G26: 387 | H26: 370 | I26: 353 | J26: 336 | K26: 315 | L26: 294 | M26: 273 | N26: 252 | O26: 231 | P26: 189 | Q26: 147 | R26: 105 | S26: 84 | T26: 75 | U26: 67 | V26: 63 | W26: 58 | X26: 54 | Y26: 50 | Z26: 42 | AA26: {=IF($D26:$Z26 = $D25:$Z25,TRUE,FALSE)} -> TRUE | AB26: TRUE | AC26: TRUE | AD26: TRUE | AE26: TRUE | AF26: TRUE | AG26: TRUE | AH26: TRUE | AI26: TRUE | AJ26: TRUE | AK26: TRUE | AL26: TRUE | AM26: TRUE | AN26: TRUE | AO26: TRUE | AP26: TRUE | AQ26: TRUE | AR26: TRUE | AS26: TRUE | AT26: TRUE | AU26: TRUE | AV26: TRUE | AW26: TRUE
B27: Exp. MOD | D27: {=IFERROR(ROUND(D25:Z25 / $E25 * 100,0),"")} -> 300 | E27: 100 | F27: 96 | G27: 92 | H27: 88 | I27: 84 | J27: 80 | K27: 75 | L27: 70 | M27: 65 | N27: 60 | O27: 55 | P27: 45 | Q27: 35 | R27: 25 | S27: 20 | T27: 18 | U27: 16 | V27: 15 | W27: 14 | X27: 13 | Y27: 12 | Z27: 10
A28: 9 | B28: Act. EXP | D28: {=INDEX(RecipeMappedExp.csv!$B$4:$B$103,$A28,1)} -> 1356 | E28: {=IFERROR(INDEX(RecipeMappedExp.csv!$C$4:$X$103,$A28,1 + E$1),"")} -> 452 | F28: {=IFERROR(INDEX(RecipeMappedExp.csv!$C$4:$X$103,$A28,1 + F$1),"")} -> 433 | G28: {=IFERROR(INDEX(RecipeMappedExp.csv!$C$4:$X$103,$A28,1 + G$1),"")} -> 415 | H28: {=IFERROR(INDEX(RecipeMappedExp.csv!$C$4:$X$103,$A28,1 + H$1),"")} -> 397 | I28: {=IFERROR(INDEX(RecipeMappedExp.csv!$C$4:$X$103,$A28,1 + I$1),"")} -> 379 | J28: {=IFERROR(INDEX(RecipeMappedExp.csv!$C$4:$X$103,$A28,1 + J$1),"")} -> 361 | K28: {=IFERROR(INDEX(RecipeMappedExp.csv!$C$4:$X$103,$A28,1 + K$1),"")} -> 339 | L28: {=IFERROR(INDEX(RecipeMappedExp.csv!$C$4:$X$103,$A28,1 + L$1),"")} -> 316 | ... Z28: {=IFERROR(INDEX(RecipeMappedExp.csv!$C$4:$X$103,$A28,1 + Z$1),"")} -> 45
B29: Exp. EXP | D29: =D28 -> 1356 | E29: {=FLOOR($D28 / 3 * $E$2:$Z$2 / 100,1)} -> 452 | F29: 433 | G29: 415 | H29: 397 | I29: 379 | J29: 361 | K29: 339 | L29: 316 | M29: 293 | N29: 271 | O29: 248 | P29: 203 | Q29: 158 | R29: 113 | S29: 90 | T29: 81 | U29: 72 | V29: 67 | W29: 63 | X29: 58 | Y29: 54 | Z29: 45 | AA29: {=IF($D29:$Z29 = $D28:$Z28,TRUE,FALSE)} -> TRUE | AB29: TRUE | AC29: TRUE | AD29: TRUE | AE29: TRUE | AF29: TRUE | AG29: TRUE | AH29: TRUE | AI29: TRUE | AJ29: TRUE | AK29: TRUE | AL29: TRUE | AM29: TRUE | AN29: TRUE | AO29: TRUE | AP29: TRUE | AQ29: TRUE | AR29: TRUE | AS29: TRUE | AT29: TRUE | AU29: TRUE | AV29: TRUE | AW29: TRUE
B30: Exp. MOD | D30: {=IFERROR(ROUND(D28:Z28 / $E28 * 100,0),"")} -> 300 | E30: 100 | F30: 96 | G30: 92 | H30: 88 | I30: 84 | J30: 80 | K30: 75 | L30: 70 | M30: 65 | N30: 60 | O30: 55 | P30: 45 | Q30: 35 | R30: 25 | S30: 20 | T30: 18 | U30: 16 | V30: 15 | W30: 14 | X30: 13 | Y30: 12 | Z30: 10
A31: 10 | B31: Act. EXP | D31: {=INDEX(RecipeMappedExp.csv!$B$4:$B$103,$A31,1)} -> 1437 | E31: {=IFERROR(INDEX(RecipeMappedExp.csv!$C$4:$X$103,$A31,1 + E$1),"")} -> 479 | F31: {=IFERROR(INDEX(RecipeMappedExp.csv!$C$4:$X$103,$A31,1 + F$1),"")} -> 459 | G31: {=IFERROR(INDEX(RecipeMappedExp.csv!$C$4:$X$103,$A31,1 + G$1),"")} -> 440 | H31: {=IFERROR(INDEX(RecipeMappedExp.csv!$C$4:$X$103,$A31,1 + H$1),"")} -> 421 | I31: {=IFERROR(INDEX(RecipeMappedExp.csv!$C$4:$X$103,$A31,1 + I$1),"")} -> 402 | J31: {=IFERROR(INDEX(RecipeMappedExp.csv!$C$4:$X$103,$A31,1 + J$1),"")} -> 383 | K31: {=IFERROR(INDEX(RecipeMappedExp.csv!$C$4:$X$103,$A31,1 + K$1),"")} -> 359 | L31: {=IFERROR(INDEX(RecipeMappedExp.csv!$C$4:$X$103,$A31,1 + L$1),"")} -> 335 | ... Z31: {=IFERROR(INDEX(RecipeMappedExp.csv!$C$4:$X$103,$A31,1 + Z$1),"")} -> 47
B32: Exp. EXP | D32: =D31 -> 1437 | E32: {=FLOOR($D31 / 3 * $E$2:$Z$2 / 100,1)} -> 479 | F32: 459 | G32: 440 | H32: 421 | I32: 402 | J32: 383 | K32: 359 | L32: 335 | M32: 311 | N32: 287 | O32: 263 | P32: 215 | Q32: 167 | R32: 119 | S32: 95 | T32: 86 | U32: 76 | V32: 71 | W32: 67 | X32: 62 | Y32: 57 | Z32: 47 | AA32: {=IF($D32:$Z32 = $D31:$Z31,TRUE,FALSE)} -> TRUE | AB32: TRUE | AC32: TRUE | AD32: TRUE | AE32: TRUE | AF32: TRUE | AG32: TRUE | AH32: TRUE | AI32: TRUE | AJ32: TRUE | AK32: TRUE | AL32: TRUE | AM32: TRUE | AN32: TRUE | AO32: TRUE | AP32: TRUE | AQ32: TRUE | AR32: TRUE | AS32: TRUE | AT32: TRUE | AU32: TRUE | AV32: TRUE | AW32: TRUE
B33: Exp. MOD | D33: {=IFERROR(ROUND(D31:Z31 / $E31 * 100,0),"")} -> 300 | E33: 100 | F33: 96 | G33: 92 | H33: 88 | I33: 84 | J33: 80 | K33: 75 | L33: 70 | M33: 65 | N33: 60 | O33: 55 | P33: 45 | Q33: 35 | R33: 25 | S33: 20 | T33: 18 | U33: 16 | V33: 15 | W33: 14 | X33: 13 | Y33: 12 | Z33: 10
A34: 11 | B34: Act. EXP | D34: {=INDEX(RecipeMappedExp.csv!$B$4:$B$103,$A34,1)} -> 1629 | E34: {=IFERROR(INDEX(RecipeMappedExp.csv!$C$4:$X$103,$A34,1 + E$1),"")} -> 543 | F34: {=IFERROR(INDEX(RecipeMappedExp.csv!$C$4:$X$103,$A34,1 + F$1),"")} -> 521 | G34: {=IFERROR(INDEX(RecipeMappedExp.csv!$C$4:$X$103,$A34,1 + G$1),"")} -> 499 | H34: {=IFERROR(INDEX(RecipeMappedExp.csv!$C$4:$X$103,$A34,1 + H$1),"")} -> 477 | I34: {=IFERROR(INDEX(RecipeMappedExp.csv!$C$4:$X$103,$A34,1 + I$1),"")} -> 456 | J34: {=IFERROR(INDEX(RecipeMappedExp.csv!$C$4:$X$103,$A34,1 + J$1),"")} -> 434 | K34: {=IFERROR(INDEX(RecipeMappedExp.csv!$C$4:$X$103,$A34,1 + K$1),"")} -> 407 | L34: {=IFERROR(INDEX(RecipeMappedExp.csv!$C$4:$X$103,$A34,1 + L$1),"")} -> 380 | ... Z34: {=IFERROR(INDEX(RecipeMappedExp.csv!$C$4:$X$103,$A34,1 + Z$1),"")} -> 54
B35: Exp. EXP | D35: =D34 -> 1629 | E35: {=FLOOR($D34 / 3 * $E$2:$Z$2 / 100,1)} -> 543 | F35: 521 | G35: 499 | H35: 477 | I35: 456 | J35: 434 | K35: 407 | L35: 380 | M35: 352 | N35: 325 | O35: 298 | P35: 244 | Q35: 190 | R35: 135 | S35: 108 | T35: 97 | U35: 86 | V35: 81 | W35: 76 | X35: 70 | Y35: 65 | Z35: 54 | AA35: {=IF($D35:$Z35 = $D34:$Z34,TRUE,FALSE)} -> TRUE | AB35: TRUE | AC35: TRUE | AD35: TRUE | AE35: TRUE | AF35: TRUE | AG35: TRUE | AH35: TRUE | AI35: TRUE | AJ35: TRUE | AK35: TRUE | AL35: TRUE | AM35: TRUE | AN35: TRUE | AO35: TRUE | AP35: TRUE | AQ35: TRUE | AR35: TRUE | AS35: TRUE | AT35: TRUE | AU35: TRUE | AV35: TRUE | AW35: TRUE
B36: Exp. MOD | D36: {=IFERROR(ROUND(D34:Z34 / $E34 * 100,0),"")} -> 300 | E36: 100 | F36: 96 | G36: 92 | H36: 88 | I36: 84 | J36: 80 | K36: 75 | L36: 70 | M36: 65 | N36: 60 | O36: 55 | P36: 45 | Q36: 35 | R36: 25 | S36: 20 | T36: 18 | U36: 16 | V36: 15 | W36: 14 | X36: 13 | Y36: 12 | Z36: 10
A37: 12 | B37: Act. EXP | D37: {=INDEX(RecipeMappedExp.csv!$B$4:$B$103,$A37,1)} -> 1725 | E37: {=IFERROR(INDEX(RecipeMappedExp.csv!$C$4:$X$103,$A37,1 + E$1),"")} -> 575 | F37: {=IFERROR(INDEX(RecipeMappedExp.csv!$C$4:$X$103,$A37,1 + F$1),"")} -> 552 | G37: {=IFERROR(INDEX(RecipeMappedExp.csv!$C$4:$X$103,$A37,1 + G$1),"")} -> 529 | H37: {=IFERROR(INDEX(RecipeMappedExp.csv!$C$4:$X$103,$A37,1 + H$1),"")} -> 506 | I37: {=IFERROR(INDEX(RecipeMappedExp.csv!$C$4:$X$103,$A37,1 + I$1),"")} -> 483 | J37: {=IFERROR(INDEX(RecipeMappedExp.csv!$C$4:$X$103,$A37,1 + J$1),"")} -> 460 | K37: {=IFERROR(INDEX(RecipeMappedExp.csv!$C$4:$X$103,$A37,1 + K$1),"")} -> 431 | L37: {=IFERROR(INDEX(RecipeMappedExp.csv!$C$4:$X$103,$A37,1 + L$1),"")} -> 402 | ... Z37: {=IFERROR(INDEX(RecipeMappedExp.csv!$C$4:$X$103,$A37,1 + Z$1),"")} -> 57
B38: Exp. EXP | D38: =D37 -> 1725 | E38: {=FLOOR($D37 / 3 * $E$2:$Z$2 / 100,1)} -> 575 | F38: 552 | G38: 529 | H38: 506 | I38: 483 | J38: 460 | K38: 431 | L38: 402 | M38: 373 | N38: 345 | O38: 316 | P38: 258 | Q38: 201 | R38: 143 | S38: 115 | T38: 103 | U38: 92 | V38: 86 | W38: 80 | X38: 74 | Y38: 69 | Z38: 57 | AA38: {=IF($D38:$Z38 = $D37:$Z37,TRUE,FALSE)} -> TRUE | AB38: TRUE | AC38: TRUE | AD38: TRUE | AE38: TRUE | AF38: TRUE | AG38: TRUE | AH38: TRUE | AI38: TRUE | AJ38: TRUE | AK38: TRUE | AL38: TRUE | AM38: TRUE | AN38: TRUE | AO38: TRUE | AP38: TRUE | AQ38: TRUE | AR38: TRUE | AS38: TRUE | AT38: TRUE | AU38: TRUE | AV38: TRUE | AW38: TRUE
B39: Exp. MOD | D39: {=IFERROR(ROUND(D37:Z37 / $E37 * 100,0),"")} -> 300 | E39: 100 | F39: 96 | G39: 92 | H39: 88 | I39: 84 | J39: 80 | K39: 75 | L39: 70 | M39: 65 | N39: 60 | O39: 55 | P39: 45 | Q39: 35 | R39: 25 | S39: 20 | T39: 18 | U39: 16 | V39: 15 | W39: 14 | X39: 13 | Y39: 12 | Z39: 10
A40: 13 | B40: Act. EXP | D40: {=INDEX(RecipeMappedExp.csv!$B$4:$B$103,$A40,1)} -> 1875 | E40: {=IFERROR(INDEX(RecipeMappedExp.csv!$C$4:$X$103,$A40,1 + E$1),"")} -> 625 | F40: {=IFERROR(INDEX(RecipeMappedExp.csv!$C$4:$X$103,$A40,1 + F$1),"")} -> 600 | G40: {=IFERROR(INDEX(RecipeMappedExp.csv!$C$4:$X$103,$A40,1 + G$1),"")} -> 575 | H40: {=IFERROR(INDEX(RecipeMappedExp.csv!$C$4:$X$103,$A40,1 + H$1),"")} -> 550 | I40: {=IFERROR(INDEX(RecipeMappedExp.csv!$C$4:$X$103,$A40,1 + I$1),"")} -> 525 | J40: {=IFERROR(INDEX(RecipeMappedExp.csv!$C$4:$X$103,$A40,1 + J$1),"")} -> 500 | K40: {=IFERROR(INDEX(RecipeMappedExp.csv!$C$4:$X$103,$A40,1 + K$1),"")} -> 468 | L40: {=IFERROR(INDEX(RecipeMappedExp.csv!$C$4:$X$103,$A40,1 + L$1),"")} -> 437 | ... Z40: {=IFERROR(INDEX(RecipeMappedExp.csv!$C$4:$X$103,$A40,1 + Z$1),"")} -> 62
...

Sheet Tests
A1: HQ Bonus Tests
A3: Class Job Level: | B3: Class Job Level: | C3: Class Job Level: | D3: Class Job Level: | E3: Class Job Level: | F3: Class Job Level: | G3: Class Job Level:
A4: 59 | B4: 58 | C4: 58 | D4: 58 | E4: 58 | F4: 58 | G4: 59
A5: Apparent Recipe Level: | B5: Apparent Recipe Level: | C5: Apparent Recipe Level: | D5: Apparent Recipe Level: | E5: Apparent Recipe Level: | F5: Apparent Recipe Level: | G5: Apparent Recipe Level:
A6: 58 | B6: 58 | C6: 58 | D6: 58 | E6: 58 | F6: 58 | G6: 58
A7: Control: | B7: Control: | C7: Control: | D7: Control: | E7: Control: | F7: Control: | G7: Control:
A8: 426 | B8: 426 | C8: 426 | D8: 426 | E8: 426 | F8: 426 | G8: 426
A9: Quality Gain: | B9: Quality Gain: | C9: Quality Gain: | D9: Quality Gain: | E9: Quality Gain: | F9: Quality Gain: | G9: Quality Gain:
A10: 1760 | B10: 2000 | C10: 2040 | D10: 1922 | E10: 1890 | F10: 1392 | G10: 1061
A11: Total Quality: | B11: Total Quality: | C11: Total Quality: | D11: Total Quality: | E11: Total Quality: | F11: Total Quality: | G11: Total Quality:
A12: 2048 | B12: 2048 | C12: 2048 | D12: 2048 | E12: 2048 | F12: 2048 | G12: 2048
A13: Quality Factor: | B13: Quality Factor: | C13: Quality Factor: | D13: Quality Factor: | E13: Quality Factor: | F13: Quality Factor: | G13: Quality Factor:
A14: =FLOOR(A10 / A12 * 100,1) -> 85 | B14: =FLOOR(B10 / B12 * 100,1) -> 97 | C14: =FLOOR(C10 / C12 * 100,1) -> 99 | D14: =FLOOR(D10 / D12 * 100,1) -> 93 | E14: =FLOOR(E10 / E12 * 100,1) -> 92 | F14: =FLOOR(F10 / F12 * 100,1) -> 67 | G14: =FLOOR(G10 / G12 * 100,1) -> 51
A15: In-Game Exp Bonus: | B15: In-Game Exp Bonus: | C15: In-Game Exp Bonus: | D15: In-Game Exp Bonus: | E15: In-Game Exp Bonus: | F15: In-Game Exp Bonus: | G15: In-Game Exp Bonus:
A16: 2.93 | B16: 2.99 | C16: 3 | D16: 2.97 | E16: 2.96 | F16: 2.74 | G16: 2.96
A17: In-Game Exp Gain: | B17: In-Game Exp Gain: | C17: In-Game Exp Gain: | D17: In-Game Exp Gain: | E17: In-Game Exp Gain: | F17: In-Game Exp Gain: | G17: In-Game Exp Gain:
A18: 65646 | B18: 69426 | C18: 69600 | D18: 69078 | E18: 68904 | F18: 65076 | G18: 57127
A19: Expected Exp Bonus: | B19: Expected Exp Bonus: | C19: Expected Exp Bonus: | D19: Expected Exp Bonus: | E19: Expected Exp Bonus: | F19: Expected Exp Bonus: | G19: Expected Exp Bonus:
A20: =VLOOKUP(A14,RecipeBonusExpTable,2,0) / 100 -> 2.93 | B20: =VLOOKUP(B14,RecipeBonusExpTable,2,0) / 100 -> 2.99 | C20: =VLOOKUP(C14,RecipeBonusExpTable,2,0) / 100 -> 3 | D20: =VLOOKUP(D14,RecipeBonusExpTable,2,0) / 100 -> 2.97 | E20: =VLOOKUP(E14,RecipeBonusExpTable,2,0) / 100 -> 2.96 | F20: =VLOOKUP(F14,RecipeBonusExpTable,2,0) / 100 -> 2.74 | G20: =VLOOKUP(G14,RecipeBonusExpTable,2,0) / 100 -> 2.42
A21: Expected Exp Gain: | B21: Expected Exp Gain: | C21: Expected Exp Gain: | D21: Expected Exp Gain: | E21: Expected Exp Gain: | F21: Expected Exp Gain: | G21: Expected Exp Gain:
A22: =FLOOR(FLOOR(VLOOKUP(A6,RecipeBaseExpTable,2,0) / 3,1) * VLOOKUP(MIN(21,MAX(0,A4 - A6)),RecipeExpModTable,2,0) / 100 * (1 + VLOOKUP(A14,RecipeBonusExpTable,2,0) / 100),1) -> 65646 | B22: =FLOOR(FLOOR(VLOOKUP(B6,RecipeBaseExpTable,2,0) / 3,1) * VLOOKUP(MIN(21,MAX(0,B4 - B6)),RecipeExpModTable,2,0) / 100 * (1 + VLOOKUP(B14,RecipeBonusExpTable,2,0) / 100),1) -> 69426 | C22: =FLOOR(FLOOR(VLOOKUP(C6,RecipeBaseExpTable,2,0) / 3,1) * VLOOKUP(MIN(21,MAX(0,C4 - C6)),RecipeExpModTable,2,0) / 100 * (1 + VLOOKUP(C14,RecipeBonusExpTable,2,0) / 100),1) -> 69600 | D22: =FLOOR(FLOOR(VLOOKUP(D6,RecipeBaseExpTable,2,0) / 3,1) * VLOOKUP(MIN(21,MAX(0,D4 - D6)),RecipeExpModTable,2,0) / 100 * (1 + VLOOKUP(D14,RecipeBonusExpTable,2,0) / 100),1) -> 69078 | E22: =FLOOR(FLOOR(VLOOKUP(E6,RecipeBaseExpTable,2,0) / 3,1) * VLOOKUP(MIN(21,MAX(0,E4 - E6)),RecipeExpModTable,2,0) / 100 * (1 + VLOOKUP(E14,RecipeBonusExpTable,2,0) / 100),1) -> 68904 | F22: =FLOOR(FLOOR(VLOOKUP(F6,RecipeBaseExpTable,2,0) / 3,1) * VLOOKUP(MIN(21,MAX(0,F4 - F6)),RecipeExpModTable,2,0) / 100 * (1 + VLOOKUP(F14,RecipeBonusExpTable,2,0) / 100),1) -> 65076 | G22: =FLOOR(FLOOR(VLOOKUP(G6,RecipeBaseExpTable,2,0) / 3,1) * VLOOKUP(MIN(21,MAX(0,G4 - G6)),RecipeExpModTable,2,0) / 100 * (1 + VLOOKUP(G14,RecipeBonusExpTable,2,0) / 100),1) -> 57127

Sheet ExpPerLevel
A1: Level | B1: Exp | C1: Total
A2: 1~2 | B2: 300 | C2: 300 | D2: =B2 -> 300
A3: 2~3 | B3: 450 | C3: 750 | D3: =B3 - B2 -> 150
A4: 3~4 | B4: 630 | C4: 1380 | D4: =B4 - B3 -> 180
A5: 4~5 | B5: 970 | C5: 2350 | D5: =B5 - B4 -> 340
A6: 5~6 | B6: 1440 | C6: 3790 | D6: =B6 - B5 -> 470
A7: 6~7 | B7: 1940 | C7: 5730 | D7: =B7 - B6 -> 500
A8: 7~8 | B8: 3000 | C8: 8730 | D8: =B8 - B7 -> 1060
A9: 8~9 | B9: 3920 | C9: 12650 | D9: =B9 - B8 -> 920
A10: 9~10 | B10: 4970 | C10: 17620 | D10: =B10 - B9 -> 1050
A11: 10~11 | B11: 5900 | C11: 23520 | D11: =B11 - B10 -> 930
A12: 11~12 | B12: 7430 | C12: 30950 | D12: =B12 - B11 -> 1530
A13: 12~13 | B13: 8620 | C13: 39570 | D13: =B13 - B12 -> 1190
A14: 13~14 | B14: 10200 | C14: 49770 | D14: =B14 - B13 -> 1580
... A90: 89~90 | B90: 10838000 | C90: 150922270 | D90: =B90 - B89 -> 379000

Sheet RecipeBaseExpTable
A1: LEVEL | B1: BASE EXP
A2: 1 | B2: 540
A3: 2 | B3: 582
A4: 3 | B4: 630
A5: 4 | B5: 795
A6: 5 | B6: 996
A7: 6 | B7: 1050
A8: 7 | B8: 1176
A9: 8 | B9: 1263
A10: 9 | B10: 1356
A11: 10 | B11: 1437
A12: 11 | B12: 1629
A13: 12 | B13: 1725
... A101: 100 | B101: 522414

Sheet RecipeExpModTable
A1: DIFF | B1: MOD
A2: 0 | B2: 100
A3: 1 | B3: 96
A4: 2 | B4: 92
A5: 3 | B5: 88
A6: 4 | B6: 84
A7: 5 | B7: 80
A8: 6 | B8: 75
A9: 7 | B9: 70
A10: 8 | B10: 65
A11: 9 | B11: 60
A12: 10 | B12: 55
A13: 11 | B13: 45
... A23: 21 | B23: 10

Sheet RecipeBonusExpTable
A1: HQ % | B1: EXP BONUS %
A2: {=SEQUENCE(101,1,0,1)} -> 0 | B2: {=FLOOR(IFS( SEQUENCE >= 81,(SEQUENCE - 81) / (99 - 81) * (300 - 291) + 291, SEQUENCE >= 71,(SEQUENCE - 71) / (80 - 71) * (290 - 281) + 281, SEQUENCE >= 51,(SEQUENCE - 51) / (70 - 51) * (280 - 242) + 242, SEQUENCE >= 41,(SEQUENCE - 41) / (50 - 41) * (240 - 213) + 213, SEQUENCE >= 31,(SEQUENCE - 31) / (40 - 31) * (210 - 174) + 174, SEQUENCE >= 21,(SEQUENCE - 21) / (30 - 21) * (170 - 125) + 125, SEQUENCE >= 0, SEQUENCE / 20 * 120),1)} -> 0
A3: 1 | B3: 6
A4: 2 | B4: 12
A5: 3 | B5: 18
A6: 4 | B6: 24
A7: 5 | B7: 30
A8: 6 | B8: 36
A9: 7 | B9: 42
A10: 8 | B10: 48
A11: 9 | B11: 54
A12: 10 | B12: 60
A13: 11 | B13: 66
A14: 12 | B14: 72
... A102: 100 | B102: 300

Sheet NotesCalculator
A1: Exp rewarded from recipes are based on the relationship between Apparent Class Job Level and Apparent Recipe Level. The Internal CrafterLevel(CLvl) and RecipeLevel(Rlvl) values used in the Crafting Formulae are not used in the Exp formulae.
A2: Exp rewarded by completing recipes above your level is the same Exp rewarded by completing recipes equal to your level.
A3: Exp rewarded by completing recipes 21 or more levels below you are the same. Concluding that the Level Difference Modifier has a minimum of 0 and a maximum of 21.
A4: Quick Synthesis has no penalty applied to exp gained. Quick synth exp is the same as manual synth with no quality gain, even if you recieve HQ from quick synth.
A5: Star count has no affect on Exp rewarded. At the same Job Level, a lv.60★★ recipe gives the same Exp reward as a Lv.60 recipe. This applies to all level ranges.
A6: First Time Completion Exp is the same amount regardless of Class Job Level.
A7: First Time Completion Exp when divided by 3 and floored, is equal to Exp Reward with a Level difference of 0. This is not TRUE when done in reverse due to the flooring done. which can be seen on lv81-90 Recipes. Confirming FTC Exp as the base.
A8: The System does not appear to apply multiple exp gains given at the same time all at once. Instead it likely computes one amount at a time, or static gains first. Then it updates your total exp and level, before computing any other exp gains.
A9: To add more clarity to the above, here are some screenshots with their details
A10: The first screenshot was done at lv31 ARM and the recipe is lv31. first time completion exp given first and I remained at lv31. Then normal recipe exp calculated after which =Floor(6216 / 3 * 100 / 100) ,and is what you get with level difference 0.
A14: The second screenshot was done at lv31 ARM and recipe is lv31. first time completion exp given first which leveled me up to lv32. Then normal recipe exp calculated after which =(Floor(6216 / 3 * 96 / 100) , and is what you get with level difference 1.
A19: Quality State represents the quality gain percentage in integer form to the total quality. This is not the same as HQ percentage.
... A95: Crafting Exp Calculator (Try it yourself!)
A97: ClassJobLevel = | C97: 99 | D97: EXP Reward = | G97: =this.ExpReward&"(+"&FLOOR((this.ExpBonus + ExpBuffs) * 100,1)&"%)" -> 766005(+360%)
A98: ApparentRecipeLevel = | C98: 99
A99: QualityGain = | C99: 2800
A100: TotalQuality = | C100: 3500
A101: ExpBuffs = | C101: 0.7
A102: f(LevelDifference) = | D102: ="MIN(21,MAX(0,"&ClassJobLevel&" - "&ApparentRecipeLevel&"))" -> MIN(21,MAX(0,99 - 99))
A103: f(LevelDifference) = | D103: =LEVELDIFFERENCE() -> 0
A104: f(ExpLevelMod) = | F104: ="VLOOKUP("&this.LevelDifference&",RecipeExpModTable,2,0)" -> VLOOKUP(0,RecipeExpModTable,2,0)
A105: f(ExpLevelMod) = | F105: =EXPLEVELMOD() -> 100
A106: f(RecipeExp) = | H106: ="FLOOR(VLOOKUP("&ApparentRecipeLevel&",RecipeBaseExpTable,2,0) / 3 * "&this.ExpLevelMod&" / 100)" -> FLOOR(VLOOKUP(99,RecipeBaseExpTable,2,0) / 3 * 100 / 100)
A107: f(RecipeExp) = | H107: =CRAFTEXP() -> 166523
A108: f(QualityFactor) = | D108: ="FLOOR("&QualityGain&" / "&TotalQuality&" * 100)" -> FLOOR(2800 / 3500 * 100)
A109: f(QualityFactor) = | D109: =QUALITYFACTOR() -> 80
A110: f(ExpBonus) = | F110: ="VLOOKUP("&this.QualityFactor&",RecipeExpBonusTable,2,0) / 100" -> VLOOKUP(80,RecipeExpBonusTable,2,0) / 100
A111: f(ExpBonus) = | F111: =EXPBONUS() -> 2.9
A112: f(ExpReward) = | H112: ="FLOOR("&this.CraftExp&" * (1 + "&this.ExpBonus&")) + FLOOR("&this.CraftExp&" * "&ExpBuffs&"))" -> FLOOR(166523 * (1 + 2.9)) + FLOOR(166523 * 0.7))
A113: f(ExpReward) = | H113: =EXPREWARD() -> 766005
